<sdf version='1.6'>
  <world name='default'>
    <light name='sun' type='directional'>
      <cast_shadows>1</cast_shadows>
      <pose frame=''>0 0 10 0 -0 0</pose>
      <diffuse>0.8 0.8 0.8 1</diffuse>
      <specular>0.2 0.2 0.2 1</specular>
      <attenuation>
        <range>1000</range>
        <constant>0.9</constant>
        <linear>0.01</linear>
        <quadratic>0.001</quadratic>
      </attenuation>
      <direction>-0.5 0.1 -0.9</direction>
    </light>
    <model name='ground_plane'>
      <static>1</static>
      <link name='link'>
        <collision name='collision'>
          <geometry>
            <plane>
              <normal>0 0 1</normal>
              <size>100 100</size>
            </plane>
          </geometry>
          <surface>
            <contact>
              <collide_bitmask>65535</collide_bitmask>
              <ode/>
            </contact>
            <friction>
              <ode>
                <mu>100</mu>
                <mu2>50</mu2>
              </ode>
              <torsional>
                <ode/>
              </torsional>
            </friction>
            <bounce/>
          </surface>
          <max_contacts>10</max_contacts>
        </collision>
        <visual name='visual'>
          <cast_shadows>0</cast_shadows>
          <geometry>
            <plane>
              <normal>0 0 1</normal>
              <size>100 100</size>
            </plane>
          </geometry>
          <material>
            <script>
              <uri>file://media/materials/scripts/gazebo.material</uri>
              <name>Gazebo/Grey</name>
            </script>
          </material>
        </visual>
        <self_collide>0</self_collide>
        <enable_wind>0</enable_wind>
        <kinematic>0</kinematic>
      </link>
    </model>
    <gravity>0 0 -9.8</gravity>
    <magnetic_field>6e-06 2.3e-05 -4.2e-05</magnetic_field>
    <atmosphere type='adiabatic'/>
    <physics name='default_physics' default='0' type='ode'>
      <max_step_size>0.001</max_step_size>
      <real_time_factor>1</real_time_factor>
      <real_time_update_rate>1000</real_time_update_rate>
    </physics>
    <scene>
      <ambient>0.4 0.4 0.4 1</ambient>
      <background>0.7 0.7 0.7 1</background>
      <shadows>1</shadows>
    </scene>
    <wind/>
    <spherical_coordinates>
      <surface_model>EARTH_WGS84</surface_model>
      <latitude_deg>0</latitude_deg>
      <longitude_deg>0</longitude_deg>
      <elevation>0</elevation>
      <heading_deg>0</heading_deg>
    </spherical_coordinates>
    <model name='Construction Barrel'>
      <link name='link'>
        <inertial>
          <pose frame=''>0 0 0.4 0 -0 0</pose>
          <mass>500</mass>
          <inertia>
            <ixx>51.2096</ixx>
            <iyy>51.2096</iyy>
            <izz>25</izz>
            <ixy>0</ixy>
            <ixz>0</ixz>
            <iyz>0</iyz>
          </inertia>
        </inertial>
        <collision name='collision'>
          <geometry>
            <mesh>
              <uri>model://construction_barrel/meshes/construction_barrel.dae</uri>
            </mesh>
          </geometry>
          <max_contacts>10</max_contacts>
          <surface>
            <contact>
              <ode/>
            </contact>
            <bounce/>
            <friction>
              <torsional>
                <ode/>
              </torsional>
              <ode/>
            </friction>
          </surface>
        </collision>
        <visual name='visual'>
          <geometry>
            <mesh>
              <uri>model://construction_barrel/meshes/construction_barrel.dae</uri>
            </mesh>
          </geometry>
        </visual>
        <self_collide>0</self_collide>
        <enable_wind>0</enable_wind>
        <kinematic>0</kinematic>
      </link>
      <pose frame=''>6.67211 2.41115 0 0 -0 0</pose>
    </model>
    <model name='Construction Cone'>
      <link name='link'>
        <collision name='collision'>
          <geometry>
            <mesh>
              <scale>10 10 10</scale>
              <uri>model://construction_cone/meshes/construction_cone.dae</uri>
            </mesh>
          </geometry>
          <max_contacts>10</max_contacts>
          <surface>
            <contact>
              <ode/>
            </contact>
            <bounce/>
            <friction>
              <torsional>
                <ode/>
              </torsional>
              <ode/>
            </friction>
          </surface>
        </collision>
        <visual name='visual'>
          <geometry>
            <mesh>
              <scale>10 10 10</scale>
              <uri>model://construction_cone/meshes/construction_cone.dae</uri>
            </mesh>
          </geometry>
        </visual>
        <self_collide>0</self_collide>
        <inertial>
          <pose frame=''>0 0 0 0 -0 0</pose>
          <inertia>
            <ixx>1</ixx>
            <ixy>0</ixy>
            <ixz>0</ixz>
            <iyy>1</iyy>
            <iyz>0</iyz>
            <izz>1</izz>
          </inertia>
          <mass>1</mass>
        </inertial>
        <enable_wind>0</enable_wind>
        <kinematic>0</kinematic>
      </link>
      <pose frame=''>8.07263 0.002528 0 0 -0 0</pose>
    </model>
    <model name='Construction Cone_0'>
      <link name='link'>
        <collision name='collision'>
          <geometry>
            <mesh>
              <scale>10 10 10</scale>
              <uri>model://construction_cone/meshes/construction_cone.dae</uri>
            </mesh>
          </geometry>
          <max_contacts>10</max_contacts>
          <surface>
            <contact>
              <ode/>
            </contact>
            <bounce/>
            <friction>
              <torsional>
                <ode/>
              </torsional>
              <ode/>
            </friction>
          </surface>
        </collision>
        <visual name='visual'>
          <geometry>
            <mesh>
              <scale>10 10 10</scale>
              <uri>model://construction_cone/meshes/construction_cone.dae</uri>
            </mesh>
          </geometry>
        </visual>
        <self_collide>0</self_collide>
        <inertial>
          <pose frame=''>0 0 0 0 -0 0</pose>
          <inertia>
            <ixx>1</ixx>
            <ixy>0</ixy>
            <ixz>0</ixz>
            <iyy>1</iyy>
            <iyz>0</iyz>
            <izz>1</izz>
          </inertia>
          <mass>1</mass>
        </inertial>
        <enable_wind>0</enable_wind>
        <kinematic>0</kinematic>
      </link>
      <pose frame=''>8.71919 -1.97014 0 0 -0 0</pose>
    </model>
    <model name='Construction Barrel_0'>
      <link name='link'>
        <inertial>
          <pose frame=''>0 0 0.4 0 -0 0</pose>
          <mass>500</mass>
          <inertia>
            <ixx>51.2096</ixx>
            <iyy>51.2096</iyy>
            <izz>25</izz>
            <ixy>0</ixy>
            <ixz>0</ixz>
            <iyz>0</iyz>
          </inertia>
        </inertial>
        <collision name='collision'>
          <geometry>
            <mesh>
              <uri>model://construction_barrel/meshes/construction_barrel.dae</uri>
            </mesh>
          </geometry>
          <max_contacts>10</max_contacts>
          <surface>
            <contact>
              <ode/>
            </contact>
            <bounce/>
            <friction>
              <torsional>
                <ode/>
              </torsional>
              <ode/>
            </friction>
          </surface>
        </collision>
        <visual name='visual'>
          <geometry>
            <mesh>
              <uri>model://construction_barrel/meshes/construction_barrel.dae</uri>
            </mesh>
          </geometry>
        </visual>
        <self_collide>0</self_collide>
        <enable_wind>0</enable_wind>
        <kinematic>0</kinematic>
      </link>
      <pose frame=''>7.10562 -3.84012 0 0 -0 0</pose>
    </model>
    <state world_name='default'>
      <sim_time>48 643000000</sim_time>
      <real_time>56 531393500</real_time>
      <wall_time>1690328235 469197000</wall_time>
      <iterations>48643</iterations>
      <model name='Construction Barrel'>
        <pose frame=''>6.67209 2.41114 -0 0 -8e-06 -4e-06</pose>
        <scale>1 1 1</scale>
        <link name='link'>
          <pose frame=''>6.67209 2.41114 -0 0 -8e-06 -4e-06</pose>
          <velocity>-0 0 -3e-06 -1e-06 -0.007919 0</velocity>
          <acceleration>7e-06 -0.401499 -1.63803 1.00375 -2.8e-05 -1.9e-05</acceleration>
          <wrench>0.003251 -200.749 -819.013 0 -0 0</wrench>
        </link>
      </model>
      <model name='Construction Barrel_0'>
        <pose frame=''>7.1056 -3.84013 -0 0 -8e-06 -4e-06</pose>
        <scale>1 1 1</scale>
        <link name='link'>
          <pose frame=''>7.1056 -3.84013 -0 0 -8e-06 -4e-06</pose>
          <velocity>-0 0 -3e-06 -1e-06 -0.007919 0</velocity>
          <acceleration>7e-06 -0.401499 -1.63803 1.00375 -2.8e-05 -1.9e-05</acceleration>
          <wrench>0.003251 -200.749 -819.013 0 -0 0</wrench>
        </link>
      </model>
      <model name='Construction Cone'>
        <pose frame=''>8.07263 0.002528 -8e-06 2e-06 -0 0</pose>
        <scale>1 1 1</scale>
        <link name='link'>
          <pose frame=''>8.07263 0.002528 -8e-06 2e-06 -0 0</pose>
          <velocity>-0 -0 -0.008812 0.000699 -0.000835 0</velocity>
          <acceleration>0 0 -9.8 0 -0 0</acceleration>
          <wrench>0 0 -9.8 0 -0 0</wrench>
        </link>
      </model>
      <model name='Construction Cone_0'>
        <pose frame=''>8.71919 -1.97014 -8e-06 2e-06 -0 0</pose>
        <scale>1 1 1</scale>
        <link name='link'>
          <pose frame=''>8.71919 -1.97014 -8e-06 2e-06 -0 0</pose>
          <velocity>-0 -0 -0.008812 0.000699 -0.000835 0</velocity>
          <acceleration>0 0 -9.8 0 -0 0</acceleration>
          <wrench>0 0 -9.8 0 -0 0</wrench>
        </link>
      </model>
      <model name='ground_plane'>
        <pose frame=''>0 0 0 0 -0 0</pose>
        <scale>1 1 1</scale>
        <link name='link'>
          <pose frame=''>0 0 0 0 -0 0</pose>
          <velocity>0 0 0 0 -0 0</velocity>
          <acceleration>0 0 0 0 -0 0</acceleration>
          <wrench>0 0 0 0 -0 0</wrench>
        </link>
      </model>
      <model name='robotic_arm'>
        <pose frame=''>-0.000286 0.004609 0.002496 -0.000518 0.001329 -0.417284</pose>
        <scale>1 1 1</scale>
        <link name='arm_segment_2_link'>
          <pose frame=''>-0.144522 -0.338685 5.2327 -0.00099 1.02187 -0.41735</pose>
          <velocity>0.280908 -0.008138 -1.22908 -3.14134 -0.482496 -3.12139</velocity>
          <acceleration>-6.28768 -1.04553 -7.14958 -1.60408 0.193419 -0.187017</acceleration>
          <wrench>-75.4521 -12.5463 -85.7949 0 -0 0</wrench>
        </link>
        <link name='arm_segment_3_link'>
          <pose frame=''>1.56806 -1.69699 6.52699 -3.14103 0.391932 2.7253</pose>
          <velocity>4.98923 0.02237 -7.08809 -3.14092 0.997923 -3.12151</velocity>
          <acceleration>-5.27123 1.17149 -13.2771 -1.54241 -0.76826 -2.47084</acceleration>
          <wrench>-126.51 28.1158 -318.649 0 -0 0</wrench>
        </link>
        <link name='bottom_base_link'>
          <pose frame=''>-0.000286 0.004609 0.002496 -0.000518 0.001329 -0.417284</pose>
          <velocity>-0.000197 -0.009056 0.097024 0.001244 0.052882 0.005176</velocity>
          <acceleration>2.94573 0.085199 7.61526 0.820763 -1.08943 0.22214</acceleration>
          <wrench>35.3487 1.02239 91.3831 0 -0 0</wrench>
        </link>
        <link name='top_base_link'>
          <pose frame=''>0.001153 0.004543 1.01249 -0.000517 0.001329 -0.416506</pose>
          <velocity>0.053227 -0.010299 0.096913 0.001271 0.052898 0.019943</velocity>
          <acceleration>1.83325 -0.441672 7.59587 0.53021 -0.873763 0.943605</acceleration>
          <wrench>43.9981 -10.6001 182.301 0 -0 0</wrench>
        </link>
      </model>
      <light name='sun'>
        <pose frame=''>0 0 10 0 -0 0</pose>
      </light>
    </state>
    <gui fullscreen='0'>
      <camera name='user_camera'>
        <pose frame=''>-5.93175 -12.7272 13.6739 0 0.723643 0.617015</pose>
        <view_controller>orbit</view_controller>
        <projection_type>perspective</projection_type>
      </camera>
    </gui>
    <model name='robotic_arm'>
      <link name='bottom_base_link'>
        <pose frame=''>0 0 0 0 -0 0</pose>
        <inertial>
          <pose frame=''>0 0 0.05 0 -0 0</pose>
          <mass>12</mass>
          <inertia>
            <ixx>2.26</ixx>
            <ixy>0</ixy>
            <ixz>0</ixz>
            <iyy>6.26</iyy>
            <iyz>0</iyz>
            <izz>8.6</izz>
          </inertia>
        </inertial>
        <collision name='bottom_base_link_collision'>
          <pose frame=''>0 0 1.01 0 -0 0</pose>
          <geometry>
            <cylinder>
              <length>2.02</length>
              <radius>1.75</radius>
            </cylinder>
          </geometry>
          <max_contacts>10</max_contacts>
          <surface>
            <contact>
              <ode/>
            </contact>
            <bounce/>
            <friction>
              <torsional>
                <ode/>
              </torsional>
              <ode/>
            </friction>
          </surface>
        </collision>
        <visual name='bottom_base_link_visual'>
          <pose frame=''>0 0 0.505 0 -0 0</pose>
          <geometry>
            <cylinder>
              <length>1.01</length>
              <radius>1.75</radius>
            </cylinder>
          </geometry>
        </visual>
        <self_collide>0</self_collide>
        <enable_wind>0</enable_wind>
        <kinematic>0</kinematic>
      </link>
      <link name='top_base_link'>
        <pose frame=''>0 0 1.01 0 -0 0</pose>
        <inertial>
          <pose frame=''>0 0 0.555 0 -0 0</pose>
          <mass>24</mass>
          <inertia>
            <ixx>10.6406</ixx>
            <ixy>0</ixy>
            <ixz>0</ixz>
            <iyy>18.6406</iyy>
            <iyz>0</iyz>
            <izz>17.2</izz>
          </inertia>
        </inertial>
        <collision name='top_base_link_collision'>
          <pose frame=''>0 0 0.505 0 -0 0</pose>
          <geometry>
            <cylinder>
              <length>2.02</length>
              <radius>1.55</radius>
            </cylinder>
          </geometry>
          <max_contacts>10</max_contacts>
          <surface>
            <contact>
              <ode/>
            </contact>
            <bounce/>
            <friction>
              <torsional>
                <ode/>
              </torsional>
              <ode/>
            </friction>
          </surface>
        </collision>
        <collision name='top_base_link_fixed_joint_lump__arm_segment_1_link_collision_1'>
          <pose frame=''>0 0 2.71 0 -0 0</pose>
          <geometry>
            <box>
              <size>1.75 0.75 4</size>
            </box>
          </geometry>
          <max_contacts>10</max_contacts>
          <surface>
            <contact>
              <ode/>
            </contact>
            <bounce/>
            <friction>
              <torsional>
                <ode/>
              </torsional>
              <ode/>
            </friction>
          </surface>
        </collision>
        <visual name='top_base_link_visual'>
          <pose frame=''>0 0 0.505 0 -0 0</pose>
          <geometry>
            <cylinder>
              <length>1.01</length>
              <radius>1.55</radius>
            </cylinder>
          </geometry>
        </visual>
        <visual name='top_base_link_fixed_joint_lump__arm_segment_1_link_visual_1'>
          <pose frame=''>0 0 2.71 0 -0 0</pose>
          <geometry>
            <box>
              <size>1.75 0.75 4</size>
            </box>
          </geometry>
        </visual>
        <self_collide>0</self_collide>
        <enable_wind>0</enable_wind>
        <kinematic>0</kinematic>
      </link>
      <joint name='base_joint' type='revolute'>
        <child>top_base_link</child>
        <parent>bottom_base_link</parent>
        <axis>
          <xyz>0 0 1</xyz>
          <limit>
            <lower>0</lower>
            <upper>3.14</upper>
            <effort>100</effort>
            <velocity>100</velocity>
          </limit>
          <dynamics>
            <spring_reference>0</spring_reference>
            <spring_stiffness>0</spring_stiffness>
          </dynamics>
          <use_parent_model_frame>0</use_parent_model_frame>
        </axis>
      </joint>
      <link name='arm_segment_2_link'>
        <pose frame=''>0 -0.375 5.23 0 -0 0</pose>
        <inertial>
          <pose frame=''>0 -0.725 1 0 -0 0</pose>
          <mass>12</mass>
          <inertia>
            <ixx>2.26</ixx>
            <ixy>0</ixy>
            <ixz>0</ixz>
            <iyy>6.26</iyy>
            <iyz>0</iyz>
            <izz>8.6</izz>
          </inertia>
        </inertial>
        <collision name='arm_segment_2_link_collision'>
          <pose frame=''>0 -0.725 1 0 -0 0</pose>
          <geometry>
            <box>
              <size>1 0.35 4</size>
            </box>
          </geometry>
          <max_contacts>10</max_contacts>
          <surface>
            <contact>
              <ode/>
            </contact>
            <bounce/>
            <friction>
              <torsional>
                <ode/>
              </torsional>
              <ode/>
            </friction>
          </surface>
        </collision>
        <visual name='arm_segment_2_link_visual'>
          <pose frame=''>0 -0.725 1 0 -0 0</pose>
          <geometry>
            <box>
              <size>1 0.35 4</size>
            </box>
          </geometry>
        </visual>
        <self_collide>0</self_collide>
        <enable_wind>0</enable_wind>
        <kinematic>0</kinematic>
      </link>
      <joint name='arm_segment_2' type='revolute'>
        <child>arm_segment_2_link</child>
        <parent>top_base_link</parent>
        <axis>
          <xyz>0 1 0</xyz>
          <limit>
            <lower>0</lower>
            <upper>3.14</upper>
            <effort>100</effort>
            <velocity>100</velocity>
          </limit>
          <dynamics>
            <spring_reference>0</spring_reference>
            <spring_stiffness>0</spring_stiffness>
          </dynamics>
          <use_parent_model_frame>0</use_parent_model_frame>
        </axis>
      </joint>
      <link name='arm_segment_3_link'>
        <pose frame=''>0 -0.925 7.71 0 -0 0</pose>
        <inertial>
          <pose frame=''>0 0.715 2 0 -0 0</pose>
          <mass>24</mass>
          <inertia>
            <ixx>28.52</ixx>
            <ixy>0</ixy>
            <ixz>0</ixz>
            <iyy>36.52</iyy>
            <iyz>0</iyz>
            <izz>17.2</izz>
          </inertia>
        </inertial>
        <collision name='arm_segment_3_link_collision'>
          <pose frame=''>0 0.715 1 0 -0 0</pose>
          <geometry>
            <box>
              <size>1 0.35 4</size>
            </box>
          </geometry>
          <max_contacts>10</max_contacts>
          <surface>
            <contact>
              <ode/>
            </contact>
            <bounce/>
            <friction>
              <torsional>
                <ode/>
              </torsional>
              <ode/>
            </friction>
          </surface>
        </collision>
        <collision name='arm_segment_3_link_fixed_joint_lump__end_of_arm_tool_link_collision_1'>
          <pose frame=''>0 0.715 3 0 -0 0</pose>
          <geometry>
            <box>
              <size>0 0 0</size>
            </box>
          </geometry>
          <max_contacts>10</max_contacts>
          <surface>
            <contact>
              <ode/>
            </contact>
            <bounce/>
            <friction>
              <torsional>
                <ode/>
              </torsional>
              <ode/>
            </friction>
          </surface>
        </collision>
        <visual name='arm_segment_3_link_visual'>
          <pose frame=''>0 0.715 1 0 -0 0</pose>
          <geometry>
            <box>
              <size>1 0.35 4</size>
            </box>
          </geometry>
        </visual>
        <visual name='arm_segment_3_link_fixed_joint_lump__end_of_arm_tool_link_visual_1'>
          <pose frame=''>0 0.715 3 0 -0 0</pose>
          <geometry>
            <box>
              <size>0 0 0</size>
            </box>
          </geometry>
        </visual>
        <gravity>1</gravity>
        <velocity_decay/>
        <sensor name='my_camera' type='camera'>
          <update_rate>20</update_rate>
          <visualize>1</visualize>
          <camera name='cam'>
            <horizontal_fov>1.39626</horizontal_fov>
            <image>
              <width>640</width>
              <height>480</height>
              <format>R8B8G8</format>
            </image>
            <clip>
              <near>0.02</near>
              <far>300</far>
            </clip>
            <noise>
              <type>gaussian</type>
              <mean>0</mean>
              <stddev>0.007</stddev>
            </noise>
          </camera>
          <plugin name='camera_controller' filename='gazebo_ros_camera.so'>
            <alwaysOn>1</alwaysOn>
            <frameName>camera_link_optical</frameName>
            <minDepth>0.1</minDepth>
            <maxDepth>500</maxDepth>
            <robotNamespace>/</robotNamespace>
          </plugin>
          <pose frame=''>-1 0.715 2.7 3.14159 -1.57079 3.14139</pose>
        </sensor>
        <self_collide>0</self_collide>
        <enable_wind>0</enable_wind>
        <kinematic>0</kinematic>
      </link>
      <joint name='arm_segment_3' type='revolute'>
        <child>arm_segment_3_link</child>
        <parent>arm_segment_2_link</parent>
        <axis>
          <xyz>0 1 0</xyz>
          <limit>
            <lower>0</lower>
            <upper>3.14</upper>
            <effort>100</effort>
            <velocity>100</velocity>
          </limit>
          <dynamics>
            <spring_reference>0</spring_reference>
            <spring_stiffness>0</spring_stiffness>
          </dynamics>
          <use_parent_model_frame>0</use_parent_model_frame>
        </axis>
      </joint>
      <static>0</static>
      <plugin name='gazebo_ros_joint_state_publisher' filename='gazebo_ros_joint_state_publisher.so'>
        <updateRate>20</updateRate>
        <jointName>base_joint, arm_segment_2, arm_segment_3</jointName>
        <alwaysOn>1</alwaysOn>
        <robotNamespace>/</robotNamespace>
      </plugin>
      <pose frame=''>0 0 0 0 -0 0</pose>
    </model>
  </world>
</sdf>
