<?xml version="1.0"?>
<robot xmlns:xacro="http://www.ros.org/wiki/xacro" name="robot">


    <xacro:include filename="robotic_arm_gazebo.xacro"/>


    <!-- links and joints -->

    <!-- world -->
    <!-- empty because it is anchorpoint for world -->
    <link name="world"></link>

    <joint name="bottom_base_joint" type="fixed">
        <origin xyz="1.5 1.0 0" rpy="0 0 0"/>
        <parent link="world"/>
        <child link="bottom_base_link"/>
    </joint>
    <link name="bottom_base_link">
        <visual>
            <origin xyz="0 0 0.505" rpy="0 0 0"/>
            <geometry>
                <cylinder length="1.01" radius="1.75" />
            </geometry>
            <material name="green">
                <color rgba="0.2 1 0.2 1"/>
            </material>
        </visual>
        <collision>
            <origin xyz="0 0 1.01" rpy="0 0 0"/>
            <geometry>
                <cylinder length="2.02" radius="1.75" />
            </geometry>
        </collision>
        <inertial>
            <origin xyz="0 0 0.05" rpy="0 0 0"/>
            <!-- I have not changed the mass yet-->
            <mass value="12" />
            <!-- I have not changed the matrix yet-->
            <inertia ixx="2.26" ixy="0.0" ixz="0.0" iyy="6.26" iyz="0.0" izz="8.6" />
        </inertial>

    <!-- top base -->
    </link>
        <joint name="base_joint" type="revolute">
        <origin xyz="0 0 1.01" rpy="0 0 0"/>
        <parent link="bottom_base_link"/>
        <child link="top_base_link"/>
        <axis xyz="0 0 1"/>
        <limit lower="0" upper="3.14" velocity="100" effort="100"/>     
    </joint>
    <link name="top_base_link">
        <visual>
            <origin xyz="0 0 0.505" rpy="0 0 0"/>
            <geometry>
                <cylinder length="1.01" radius="1.55" />
            </geometry>
            <material name="green">
                <color rgba="0.2 1 0.2 1"/>
            </material>
        </visual>
        <collision>
            <origin xyz="0 0 0.505" rpy="0 0 0"/>
            <geometry>
                <cylinder length="2.02" radius="1.55" />
            </geometry>
        </collision>
        <inertial>
            <origin xyz="0 0 0.05" rpy="0 0 0"/>
            <!-- I have not changed the mass yet-->
            <mass value="12" />
            <!-- I have not changed the matrix yet-->
            <inertia ixx="2.26" ixy="0.0" ixz="0.0" iyy="6.26" iyz="0.0" izz="8.6" />
        </inertial>
    </link>
    <!-- arm segment 1 -->
    <joint name="arm_segment_1" type="fixed">
        <origin xyz="0 0 1.01" rpy="0 0 0"/>
        <parent link="top_base_link" />
        <child link="arm_segment_1_link" />
    </joint>
    <link name="arm_segment_1_link">
        <visual>
            <origin xyz="0 0 1.7" rpy="0 0 0"/>
            <geometry>
                <box size="1.75 0.75 4" />
            </geometry>
            <material name="green">
                <color rgba="0.2 1 0.2 1"/>
            </material>
        </visual>
        <collision>
            <origin xyz="0 0 1.7" rpy="0 0 0"/>
            <geometry>
                <box size="1.75 0.75 4" />
            </geometry>
        </collision>
        <inertial>
            <origin xyz="0 0 0" rpy="0 0 0"/>
            <!-- I have not changed the mass yet-->
            <mass value="12" />
            <!-- I have not changed the matrix yet-->
            <inertia ixx="2.26" ixy="0.0" ixz="0.0" iyy="6.26" iyz="0.0" izz="8.6" />
        </inertial>
    </link>
    <!-- arm segment 2 -->
    <joint name="arm_segment_2" type="revolute">
        <origin xyz="0 -0.375 3.21" rpy="0 0 0"/>
        <parent link="arm_segment_1_link" />
        <child link="arm_segment_2_link" />
        <axis xyz="0 1 0"/>
        <limit lower="0" upper="3.14" velocity="100" effort="100"/>    
    </joint>
    <link name="arm_segment_2_link">
        <visual>
            <!-- .55 is gap of between links + .175 is half of the width of the arm segment 2-->
            <origin xyz="0 -0.725 1" rpy="0 0 0"/>
            <geometry>
                <box size="1 0.35 4" />
            </geometry>
            <material name="green">
                <color rgba="0.2 1 0.2 1"/>
            </material>
        </visual>
        <collision>
            <origin xyz="0 -0.725 1" rpy="0 0 0"/>
            <geometry>
                <box size="1 0.35 4" />
            </geometry>
        </collision>
        <inertial>
            <origin xyz="0 -0.725 1" rpy="0 0 0"/>
            <!-- I have not changed the mass yet-->
            <mass value="12" />
            <!-- I have not changed the matrix yet-->
            <inertia ixx="2.26" ixy="0.0" ixz="0.0" iyy="6.26" iyz="0.0" izz="8.6" />
        </inertial>
    </link>
    <!-- arm segment 3 -->
    <joint name="arm_segment_3" type="revolute">
        <origin xyz="0 -0.55 2.48" rpy="0 0 0"/>
        <parent link="arm_segment_2_link" />
        <child link="arm_segment_3_link" />
        <axis xyz="0 1 0"/>
        <limit lower="0" upper="3.14" velocity="100" effort="100"/>    
    </joint>
    <link name="arm_segment_3_link">
        <visual>
            <origin xyz="0 0.715 1" rpy="0 0 0"/>
            <geometry>
                <box size="1 0.35 4" />
            </geometry>
            <material name="green">
                <color rgba="0.2 1 0.2 1"/>
            </material>
        </visual>
        <collision>
            <origin xyz="0 0.715 1" rpy="0 0 0"/>
            <geometry>
                <box size="1 0.35 4" />
            </geometry>
        </collision>
        <inertial>
            <origin xyz="0 0.715 1" rpy="0 0 0"/>
            <!-- I have not changed the mass yet-->
            <mass value="12" />
            <!-- I have not changed the matrix yet-->
            <inertia ixx="2.26" ixy="0.0" ixz="0.0" iyy="6.26" iyz="0.0" izz="8.6" />
        </inertial>
    </link>
    <!-- end of arm -->
    <joint name="end_of_arm" type="fixed">
        <origin xyz="0 0.715 3" rpy="0 0 0"/>
        <parent link="arm_segment_3_link" /> 
        <child link="end_of_arm_tool_link" />
    </joint>
    <link name="end_of_arm_tool_link">
        <visual>
            <origin xyz="0 0 0" rpy="0 0 0"/>
            <geometry>
                <box size="0 0 0" />
            </geometry>
            <material name="green">
                <color rgba="0.2 1 0.2 1"/>
            </material>
        </visual>
        <collision>
            <origin xyz="0 0 0" rpy="0 0 0"/>
            <geometry>
                <box size="0 0 0" />
            </geometry>
        </collision>
        <inertial>
            <origin xyz="0 0 0" rpy="0 0 0"/>
            <!-- I have not changed the mass yet-->
            <mass value="12" />
            <!-- I have not changed the matrix yet-->
            <inertia ixx="2.26" ixy="0.0" ixz="0.0" iyy="6.26" iyz="0.0" izz="8.6" />
        </inertial>
    </link>
</robot>